[2024-10-09 16:16:07,550] {taskinstance.py:896} INFO - Dependencies all met for <TaskInstance: mssql_dag.query_receipt 2024-10-09T16:16:05.420658+00:00 [queued]>
[2024-10-09 16:16:07,567] {taskinstance.py:896} INFO - Dependencies all met for <TaskInstance: mssql_dag.query_receipt 2024-10-09T16:16:05.420658+00:00 [queued]>
[2024-10-09 16:16:07,569] {taskinstance.py:1087} INFO - 
--------------------------------------------------------------------------------
[2024-10-09 16:16:07,570] {taskinstance.py:1088} INFO - Starting attempt 1 of 2
[2024-10-09 16:16:07,571] {taskinstance.py:1089} INFO - 
--------------------------------------------------------------------------------
[2024-10-09 16:16:07,589] {taskinstance.py:1107} INFO - Executing <Task(PythonOperator): query_receipt> on 2024-10-09T16:16:05.420658+00:00
[2024-10-09 16:16:07,595] {standard_task_runner.py:52} INFO - Started process 17366 to run task
[2024-10-09 16:16:07,599] {standard_task_runner.py:76} INFO - Running: ['***', 'tasks', 'run', 'mssql_dag', 'query_receipt', '2024-10-09T16:16:05.420658+00:00', '--job-id', '100', '--pool', 'default_pool', '--raw', '--subdir', 'DAGS_FOLDER/mssql_dag.py', '--cfg-path', '/tmp/tmpc8dogcnd', '--error-file', '/tmp/tmpaz0yhgm0']
[2024-10-09 16:16:07,604] {standard_task_runner.py:77} INFO - Job 100: Subtask query_receipt
[2024-10-09 16:16:07,642] {logging_mixin.py:104} INFO - Running <TaskInstance: mssql_dag.query_receipt 2024-10-09T16:16:05.420658+00:00 [running]> on host da843a407010
[2024-10-09 16:16:07,679] {taskinstance.py:1302} INFO - Exporting the following env vars:
AIRFLOW_CTX_DAG_OWNER=***
AIRFLOW_CTX_DAG_ID=mssql_dag
AIRFLOW_CTX_TASK_ID=query_receipt
AIRFLOW_CTX_EXECUTION_DATE=2024-10-09T16:16:05.420658+00:00
AIRFLOW_CTX_DAG_RUN_ID=manual__2024-10-09T16:16:05.420658+00:00
[2024-10-09 16:16:28,473] {taskinstance.py:1501} ERROR - Task failed with exception
Traceback (most recent call last):
  File "src/pymssql/_pymssql.pyx", line 650, in pymssql._pymssql.connect
  File "src/pymssql/_mssql.pyx", line 2155, in pymssql._mssql.connect
  File "src/pymssql/_mssql.pyx", line 712, in pymssql._mssql.MSSQLConnection.__init__
  File "src/pymssql/_mssql.pyx", line 1881, in pymssql._mssql.maybe_raise_MSSQLDatabaseException
  File "src/pymssql/_mssql.pyx", line 1898, in pymssql._mssql.raise_MSSQLDatabaseException
pymssql._mssql.MSSQLDatabaseException: (20009, b'DB-Lib error message 20009, severity 9:\nUnable to connect: Adaptive Server is unavailable or does not exist (10.0.1.190)\nNet-Lib error during Connection refused (111)\nDB-Lib error message 20009, severity 9:\nUnable to connect: Adaptive Server is unavailable or does not exist (10.0.1.190)\nNet-Lib error during Connection refused (111)\n')

During handling of the above exception, another exception occurred:

Traceback (most recent call last):
  File "/opt/airflow/dags/mssql_dag.py", line 25, in connect_mssql
    charset='UTF-8'
  File "src/pymssql/_pymssql.pyx", line 659, in pymssql._pymssql.connect
pymssql.exceptions.OperationalError: (20009, b'DB-Lib error message 20009, severity 9:\nUnable to connect: Adaptive Server is unavailable or does not exist (10.0.1.190)\nNet-Lib error during Connection refused (111)\nDB-Lib error message 20009, severity 9:\nUnable to connect: Adaptive Server is unavailable or does not exist (10.0.1.190)\nNet-Lib error during Connection refused (111)\n')

During handling of the above exception, another exception occurred:

Traceback (most recent call last):
  File "/home/airflow/.local/lib/python3.6/site-packages/airflow/models/taskinstance.py", line 1157, in _run_raw_task
    self._prepare_and_execute_task_with_callbacks(context, task)
  File "/home/airflow/.local/lib/python3.6/site-packages/airflow/models/taskinstance.py", line 1331, in _prepare_and_execute_task_with_callbacks
    result = self._execute_task(context, task_copy)
  File "/home/airflow/.local/lib/python3.6/site-packages/airflow/models/taskinstance.py", line 1361, in _execute_task
    result = task_copy.execute(context=context)
  File "/home/airflow/.local/lib/python3.6/site-packages/airflow/operators/python.py", line 150, in execute
    return_value = self.execute_callable()
  File "/home/airflow/.local/lib/python3.6/site-packages/airflow/operators/python.py", line 161, in execute_callable
    return self.python_callable(*self.op_args, **self.op_kwargs)
  File "/opt/airflow/dags/mssql_dag.py", line 38, in query_table
    connection = connect_mssql()
  File "/opt/airflow/dags/mssql_dag.py", line 29, in connect_mssql
    raise RuntimeError(f"Error connecting to MSSQL: {e}")
RuntimeError: Error connecting to MSSQL: (20009, b'DB-Lib error message 20009, severity 9:\nUnable to connect: Adaptive Server is unavailable or does not exist (10.0.1.190)\nNet-Lib error during Connection refused (111)\nDB-Lib error message 20009, severity 9:\nUnable to connect: Adaptive Server is unavailable or does not exist (10.0.1.190)\nNet-Lib error during Connection refused (111)\n')
[2024-10-09 16:16:28,482] {taskinstance.py:1551} INFO - Marking task as UP_FOR_RETRY. dag_id=mssql_dag, task_id=query_receipt, execution_date=20241009T161605, start_date=20241009T161607, end_date=20241009T161628
[2024-10-09 16:16:28,534] {local_task_job.py:149} INFO - Task exited with return code 1
