[2024-10-09 08:48:42,826] {taskinstance.py:896} INFO - Dependencies all met for <TaskInstance: mssql_dag.query_contract 2024-10-09T08:48:41.154024+00:00 [queued]>
[2024-10-09 08:48:42,834] {taskinstance.py:896} INFO - Dependencies all met for <TaskInstance: mssql_dag.query_contract 2024-10-09T08:48:41.154024+00:00 [queued]>
[2024-10-09 08:48:42,835] {taskinstance.py:1087} INFO - 
--------------------------------------------------------------------------------
[2024-10-09 08:48:42,836] {taskinstance.py:1088} INFO - Starting attempt 1 of 2
[2024-10-09 08:48:42,837] {taskinstance.py:1089} INFO - 
--------------------------------------------------------------------------------
[2024-10-09 08:48:42,847] {taskinstance.py:1107} INFO - Executing <Task(PythonOperator): query_contract> on 2024-10-09T08:48:41.154024+00:00
[2024-10-09 08:48:42,851] {standard_task_runner.py:52} INFO - Started process 90379 to run task
[2024-10-09 08:48:42,854] {standard_task_runner.py:76} INFO - Running: ['***', 'tasks', 'run', 'mssql_dag', 'query_contract', '2024-10-09T08:48:41.154024+00:00', '--job-id', '25', '--pool', 'default_pool', '--raw', '--subdir', 'DAGS_FOLDER/mssql_dag.py', '--cfg-path', '/tmp/tmpfy0xqpv5', '--error-file', '/tmp/tmpus2qwh74']
[2024-10-09 08:48:42,857] {standard_task_runner.py:77} INFO - Job 25: Subtask query_contract
[2024-10-09 08:48:42,885] {logging_mixin.py:104} INFO - Running <TaskInstance: mssql_dag.query_contract 2024-10-09T08:48:41.154024+00:00 [running]> on host da843a407010
[2024-10-09 08:48:42,915] {taskinstance.py:1302} INFO - Exporting the following env vars:
AIRFLOW_CTX_DAG_OWNER=***
AIRFLOW_CTX_DAG_ID=mssql_dag
AIRFLOW_CTX_TASK_ID=query_contract
AIRFLOW_CTX_EXECUTION_DATE=2024-10-09T08:48:41.154024+00:00
AIRFLOW_CTX_DAG_RUN_ID=manual__2024-10-09T08:48:41.154024+00:00
[2024-10-09 08:48:42,951] {taskinstance.py:1501} ERROR - Task failed with exception
Traceback (most recent call last):
  File "/home/airflow/.local/lib/python3.6/site-packages/airflow/models/taskinstance.py", line 1157, in _run_raw_task
    self._prepare_and_execute_task_with_callbacks(context, task)
  File "/home/airflow/.local/lib/python3.6/site-packages/airflow/models/taskinstance.py", line 1331, in _prepare_and_execute_task_with_callbacks
    result = self._execute_task(context, task_copy)
  File "/home/airflow/.local/lib/python3.6/site-packages/airflow/models/taskinstance.py", line 1361, in _execute_task
    result = task_copy.execute(context=context)
  File "/home/airflow/.local/lib/python3.6/site-packages/airflow/operators/python.py", line 150, in execute
    return_value = self.execute_callable()
  File "/home/airflow/.local/lib/python3.6/site-packages/airflow/operators/python.py", line 161, in execute_callable
    return self.python_callable(*self.op_args, **self.op_kwargs)
  File "/opt/airflow/dags/mssql_dag.py", line 49, in query_table
    df_receipt = connection.execute_query(query)
AttributeError: 'pymssql._pymssql.Connection' object has no attribute 'execute_query'
[2024-10-09 08:48:42,956] {taskinstance.py:1551} INFO - Marking task as UP_FOR_RETRY. dag_id=mssql_dag, task_id=query_contract, execution_date=20241009T084841, start_date=20241009T084842, end_date=20241009T084842
[2024-10-09 08:48:42,986] {local_task_job.py:149} INFO - Task exited with return code 1
