[2024-10-10 03:32:43,854] {taskinstance.py:896} INFO - Dependencies all met for <TaskInstance: mssql_dag.clean2_receipt 2024-10-10T03:32:35.890070+00:00 [queued]>
[2024-10-10 03:32:43,865] {taskinstance.py:896} INFO - Dependencies all met for <TaskInstance: mssql_dag.clean2_receipt 2024-10-10T03:32:35.890070+00:00 [queued]>
[2024-10-10 03:32:43,878] {taskinstance.py:1087} INFO - 
--------------------------------------------------------------------------------
[2024-10-10 03:32:43,883] {taskinstance.py:1088} INFO - Starting attempt 1 of 2
[2024-10-10 03:32:43,883] {taskinstance.py:1089} INFO - 
--------------------------------------------------------------------------------
[2024-10-10 03:32:43,895] {taskinstance.py:1107} INFO - Executing <Task(PythonOperator): clean2_receipt> on 2024-10-10T03:32:35.890070+00:00
[2024-10-10 03:32:43,900] {standard_task_runner.py:52} INFO - Started process 1499 to run task
[2024-10-10 03:32:43,903] {standard_task_runner.py:76} INFO - Running: ['***', 'tasks', 'run', 'mssql_dag', 'clean2_receipt', '2024-10-10T03:32:35.890070+00:00', '--job-id', '327', '--pool', 'default_pool', '--raw', '--subdir', 'DAGS_FOLDER/mssql_dag.py', '--cfg-path', '/tmp/tmp27qmummu', '--error-file', '/tmp/tmpgiwniou8']
[2024-10-10 03:32:43,906] {standard_task_runner.py:77} INFO - Job 327: Subtask clean2_receipt
[2024-10-10 03:32:43,939] {logging_mixin.py:104} INFO - Running <TaskInstance: mssql_dag.clean2_receipt 2024-10-10T03:32:35.890070+00:00 [running]> on host da843a407010
[2024-10-10 03:32:43,978] {taskinstance.py:1302} INFO - Exporting the following env vars:
AIRFLOW_CTX_DAG_OWNER=***
AIRFLOW_CTX_DAG_ID=mssql_dag
AIRFLOW_CTX_TASK_ID=clean2_receipt
AIRFLOW_CTX_EXECUTION_DATE=2024-10-10T03:32:35.890070+00:00
AIRFLOW_CTX_DAG_RUN_ID=manual__2024-10-10T03:32:35.890070+00:00
[2024-10-10 03:32:43,980] {taskinstance.py:1501} ERROR - Task failed with exception
Traceback (most recent call last):
  File "/home/airflow/.local/lib/python3.6/site-packages/pandas/core/indexes/base.py", line 2898, in get_loc
    return self._engine.get_loc(casted_key)
  File "pandas/_libs/index.pyx", line 70, in pandas._libs.index.IndexEngine.get_loc
  File "pandas/_libs/index.pyx", line 101, in pandas._libs.index.IndexEngine.get_loc
  File "pandas/_libs/hashtable_class_helper.pxi", line 1675, in pandas._libs.hashtable.PyObjectHashTable.get_item
  File "pandas/_libs/hashtable_class_helper.pxi", line 1683, in pandas._libs.hashtable.PyObjectHashTable.get_item
KeyError: 'PAY_SAVING_DOC_NO'

The above exception was the direct cause of the following exception:

Traceback (most recent call last):
  File "/home/airflow/.local/lib/python3.6/site-packages/airflow/models/taskinstance.py", line 1157, in _run_raw_task
    self._prepare_and_execute_task_with_callbacks(context, task)
  File "/home/airflow/.local/lib/python3.6/site-packages/airflow/models/taskinstance.py", line 1331, in _prepare_and_execute_task_with_callbacks
    result = self._execute_task(context, task_copy)
  File "/home/airflow/.local/lib/python3.6/site-packages/airflow/models/taskinstance.py", line 1361, in _execute_task
    result = task_copy.execute(context=context)
  File "/home/airflow/.local/lib/python3.6/site-packages/airflow/operators/python.py", line 150, in execute
    return_value = self.execute_callable()
  File "/home/airflow/.local/lib/python3.6/site-packages/airflow/operators/python.py", line 161, in execute_callable
    return self.python_callable(*self.op_args, **self.op_kwargs)
  File "/opt/airflow/dags/mssql_dag.py", line 312, in clean2_receipt
    df_receipt = clean_column(df_receipt, column, dtype)
  File "/opt/airflow/dags/mssql_dag.py", line 282, in clean_column
    df[column_name] = pd.to_numeric(df[column_name], errors='coerce')
  File "/home/airflow/.local/lib/python3.6/site-packages/pandas/core/frame.py", line 2906, in __getitem__
    indexer = self.columns.get_loc(key)
  File "/home/airflow/.local/lib/python3.6/site-packages/pandas/core/indexes/base.py", line 2900, in get_loc
    raise KeyError(key) from err
KeyError: 'PAY_SAVING_DOC_NO'
[2024-10-10 03:32:43,992] {taskinstance.py:1551} INFO - Marking task as UP_FOR_RETRY. dag_id=mssql_dag, task_id=clean2_receipt, execution_date=20241010T033235, start_date=20241010T033243, end_date=20241010T033243
[2024-10-10 03:32:44,036] {local_task_job.py:149} INFO - Task exited with return code 1
