[2024-10-09 09:17:32,710] {taskinstance.py:896} INFO - Dependencies all met for <TaskInstance: mssql_dag.query_member 2024-10-09T09:17:30.971724+00:00 [queued]>
[2024-10-09 09:17:32,718] {taskinstance.py:896} INFO - Dependencies all met for <TaskInstance: mssql_dag.query_member 2024-10-09T09:17:30.971724+00:00 [queued]>
[2024-10-09 09:17:32,719] {taskinstance.py:1087} INFO - 
--------------------------------------------------------------------------------
[2024-10-09 09:17:32,719] {taskinstance.py:1088} INFO - Starting attempt 1 of 2
[2024-10-09 09:17:32,720] {taskinstance.py:1089} INFO - 
--------------------------------------------------------------------------------
[2024-10-09 09:17:32,728] {taskinstance.py:1107} INFO - Executing <Task(PythonOperator): query_member> on 2024-10-09T09:17:30.971724+00:00
[2024-10-09 09:17:32,732] {standard_task_runner.py:52} INFO - Started process 5916 to run task
[2024-10-09 09:17:32,734] {standard_task_runner.py:76} INFO - Running: ['***', 'tasks', 'run', 'mssql_dag', 'query_member', '2024-10-09T09:17:30.971724+00:00', '--job-id', '67', '--pool', 'default_pool', '--raw', '--subdir', 'DAGS_FOLDER/mssql_dag.py', '--cfg-path', '/tmp/tmpibuzte6v', '--error-file', '/tmp/tmp_coerrfr']
[2024-10-09 09:17:32,737] {standard_task_runner.py:77} INFO - Job 67: Subtask query_member
[2024-10-09 09:17:32,767] {logging_mixin.py:104} INFO - Running <TaskInstance: mssql_dag.query_member 2024-10-09T09:17:30.971724+00:00 [running]> on host da843a407010
[2024-10-09 09:17:32,799] {taskinstance.py:1302} INFO - Exporting the following env vars:
AIRFLOW_CTX_DAG_OWNER=***
AIRFLOW_CTX_DAG_ID=mssql_dag
AIRFLOW_CTX_TASK_ID=query_member
AIRFLOW_CTX_EXECUTION_DATE=2024-10-09T09:17:30.971724+00:00
AIRFLOW_CTX_DAG_RUN_ID=manual__2024-10-09T09:17:30.971724+00:00
[2024-10-09 09:17:32,800] {taskinstance.py:1501} ERROR - Task failed with exception
Traceback (most recent call last):
  File "/home/airflow/.local/lib/python3.6/site-packages/airflow/models/taskinstance.py", line 1157, in _run_raw_task
    self._prepare_and_execute_task_with_callbacks(context, task)
  File "/home/airflow/.local/lib/python3.6/site-packages/airflow/models/taskinstance.py", line 1331, in _prepare_and_execute_task_with_callbacks
    result = self._execute_task(context, task_copy)
  File "/home/airflow/.local/lib/python3.6/site-packages/airflow/models/taskinstance.py", line 1361, in _execute_task
    result = task_copy.execute(context=context)
  File "/home/airflow/.local/lib/python3.6/site-packages/airflow/operators/python.py", line 150, in execute
    return_value = self.execute_callable()
  File "/home/airflow/.local/lib/python3.6/site-packages/airflow/operators/python.py", line 161, in execute_callable
    return self.python_callable(*self.op_args, **self.op_kwargs)
  File "/opt/airflow/dags/mssql_dag.py", line 38, in query_table
    if connection is None:
UnboundLocalError: local variable 'connection' referenced before assignment
[2024-10-09 09:17:32,813] {taskinstance.py:1551} INFO - Marking task as UP_FOR_RETRY. dag_id=mssql_dag, task_id=query_member, execution_date=20241009T091730, start_date=20241009T091732, end_date=20241009T091732
[2024-10-09 09:17:32,866] {local_task_job.py:149} INFO - Task exited with return code 1
