[2024-10-10 01:54:39,299] {taskinstance.py:896} INFO - Dependencies all met for <TaskInstance: mssql_dag.print_receipt_detail 2024-10-10T01:54:35.970892+00:00 [queued]>
[2024-10-10 01:54:39,307] {taskinstance.py:896} INFO - Dependencies all met for <TaskInstance: mssql_dag.print_receipt_detail 2024-10-10T01:54:35.970892+00:00 [queued]>
[2024-10-10 01:54:39,308] {taskinstance.py:1087} INFO - 
--------------------------------------------------------------------------------
[2024-10-10 01:54:39,309] {taskinstance.py:1088} INFO - Starting attempt 1 of 2
[2024-10-10 01:54:39,309] {taskinstance.py:1089} INFO - 
--------------------------------------------------------------------------------
[2024-10-10 01:54:39,319] {taskinstance.py:1107} INFO - Executing <Task(PythonOperator): print_receipt_detail> on 2024-10-10T01:54:35.970892+00:00
[2024-10-10 01:54:39,323] {standard_task_runner.py:52} INFO - Started process 49867 to run task
[2024-10-10 01:54:39,326] {standard_task_runner.py:76} INFO - Running: ['***', 'tasks', 'run', 'mssql_dag', 'print_receipt_detail', '2024-10-10T01:54:35.970892+00:00', '--job-id', '217', '--pool', 'default_pool', '--raw', '--subdir', 'DAGS_FOLDER/mssql_dag.py', '--cfg-path', '/tmp/tmpr6_jg6jn', '--error-file', '/tmp/tmpei7w8oz_']
[2024-10-10 01:54:39,329] {standard_task_runner.py:77} INFO - Job 217: Subtask print_receipt_detail
[2024-10-10 01:54:39,358] {logging_mixin.py:104} INFO - Running <TaskInstance: mssql_dag.print_receipt_detail 2024-10-10T01:54:35.970892+00:00 [running]> on host da843a407010
[2024-10-10 01:54:39,392] {taskinstance.py:1302} INFO - Exporting the following env vars:
AIRFLOW_CTX_DAG_OWNER=***
AIRFLOW_CTX_DAG_ID=mssql_dag
AIRFLOW_CTX_TASK_ID=print_receipt_detail
AIRFLOW_CTX_EXECUTION_DATE=2024-10-10T01:54:35.970892+00:00
AIRFLOW_CTX_DAG_RUN_ID=manual__2024-10-10T01:54:35.970892+00:00
[2024-10-10 01:55:24,771] {local_task_job.py:198} WARNING - State of this instance has been externally set to failed. Terminating instance.
[2024-10-10 01:55:24,776] {process_utils.py:100} INFO - Sending Signals.SIGTERM to GPID 49867
[2024-10-10 01:55:24,779] {taskinstance.py:1284} ERROR - Received SIGTERM. Terminating subprocesses.
[2024-10-10 01:55:24,781] {logging_mixin.py:104} INFO - Error inserting DataFrame: Task received SIGTERM signal
[2024-10-10 01:55:24,813] {logging_mixin.py:104} INFO - The DataFrame for table 'receipt' is empty.
[2024-10-10 01:55:24,814] {python.py:151} INFO - Done. Returned value was: None
[2024-10-10 01:55:24,821] {taskinstance.py:1211} INFO - Marking task as SUCCESS. dag_id=mssql_dag, task_id=print_receipt_detail, execution_date=20241010T015435, start_date=20241010T015439, end_date=20241010T015524
[2024-10-10 01:55:24,839] {taskinstance.py:1265} INFO - 1 downstream tasks scheduled from follow-on schedule check
[2024-10-10 01:55:24,869] {process_utils.py:66} INFO - Process psutil.Process(pid=49867, status='terminated', exitcode=0, started='01:54:39') (49867) terminated with exit code 0
