[2024-10-10 03:11:03,998] {taskinstance.py:896} INFO - Dependencies all met for <TaskInstance: mssql_dag.clean1_contract 2024-10-10T03:10:58.109009+00:00 [queued]>
[2024-10-10 03:11:04,006] {taskinstance.py:896} INFO - Dependencies all met for <TaskInstance: mssql_dag.clean1_contract 2024-10-10T03:10:58.109009+00:00 [queued]>
[2024-10-10 03:11:04,007] {taskinstance.py:1087} INFO - 
--------------------------------------------------------------------------------
[2024-10-10 03:11:04,008] {taskinstance.py:1088} INFO - Starting attempt 1 of 2
[2024-10-10 03:11:04,008] {taskinstance.py:1089} INFO - 
--------------------------------------------------------------------------------
[2024-10-10 03:11:04,019] {taskinstance.py:1107} INFO - Executing <Task(PythonOperator): clean1_contract> on 2024-10-10T03:10:58.109009+00:00
[2024-10-10 03:11:04,023] {standard_task_runner.py:52} INFO - Started process 89841 to run task
[2024-10-10 03:11:04,025] {standard_task_runner.py:76} INFO - Running: ['***', 'tasks', 'run', 'mssql_dag', 'clean1_contract', '2024-10-10T03:10:58.109009+00:00', '--job-id', '298', '--pool', 'default_pool', '--raw', '--subdir', 'DAGS_FOLDER/mssql_dag.py', '--cfg-path', '/tmp/tmpcypsroei', '--error-file', '/tmp/tmpmqntbuzw']
[2024-10-10 03:11:04,028] {standard_task_runner.py:77} INFO - Job 298: Subtask clean1_contract
[2024-10-10 03:11:04,063] {logging_mixin.py:104} INFO - Running <TaskInstance: mssql_dag.clean1_contract 2024-10-10T03:10:58.109009+00:00 [running]> on host da843a407010
[2024-10-10 03:11:04,095] {taskinstance.py:1302} INFO - Exporting the following env vars:
AIRFLOW_CTX_DAG_OWNER=***
AIRFLOW_CTX_DAG_ID=mssql_dag
AIRFLOW_CTX_TASK_ID=clean1_contract
AIRFLOW_CTX_EXECUTION_DATE=2024-10-10T03:10:58.109009+00:00
AIRFLOW_CTX_DAG_RUN_ID=manual__2024-10-10T03:10:58.109009+00:00
[2024-10-10 03:11:04,102] {taskinstance.py:1501} ERROR - Task failed with exception
Traceback (most recent call last):
  File "/home/airflow/.local/lib/python3.6/site-packages/pandas/core/indexes/base.py", line 2898, in get_loc
    return self._engine.get_loc(casted_key)
  File "pandas/_libs/index.pyx", line 70, in pandas._libs.index.IndexEngine.get_loc
  File "pandas/_libs/index.pyx", line 101, in pandas._libs.index.IndexEngine.get_loc
  File "pandas/_libs/hashtable_class_helper.pxi", line 1675, in pandas._libs.hashtable.PyObjectHashTable.get_item
  File "pandas/_libs/hashtable_class_helper.pxi", line 1683, in pandas._libs.hashtable.PyObjectHashTable.get_item
KeyError: 'PROM_PERD_AMT_ADD_NEXT'

The above exception was the direct cause of the following exception:

Traceback (most recent call last):
  File "/home/airflow/.local/lib/python3.6/site-packages/airflow/models/taskinstance.py", line 1157, in _run_raw_task
    self._prepare_and_execute_task_with_callbacks(context, task)
  File "/home/airflow/.local/lib/python3.6/site-packages/airflow/models/taskinstance.py", line 1331, in _prepare_and_execute_task_with_callbacks
    result = self._execute_task(context, task_copy)
  File "/home/airflow/.local/lib/python3.6/site-packages/airflow/models/taskinstance.py", line 1361, in _execute_task
    result = task_copy.execute(context=context)
  File "/home/airflow/.local/lib/python3.6/site-packages/airflow/operators/python.py", line 150, in execute
    return_value = self.execute_callable()
  File "/home/airflow/.local/lib/python3.6/site-packages/airflow/operators/python.py", line 161, in execute_callable
    return self.python_callable(*self.op_args, **self.op_kwargs)
  File "/opt/airflow/dags/mssql_dag.py", line 263, in clean1_contract
    df_contract['PROM_PERD_AMT_ADD_NEXT'] = df_contract['PROM_PERD_AMT_ADD_NEXT'].str.strip().replace('', None)
  File "/home/airflow/.local/lib/python3.6/site-packages/pandas/core/frame.py", line 2906, in __getitem__
    indexer = self.columns.get_loc(key)
  File "/home/airflow/.local/lib/python3.6/site-packages/pandas/core/indexes/base.py", line 2900, in get_loc
    raise KeyError(key) from err
KeyError: 'PROM_PERD_AMT_ADD_NEXT'
[2024-10-10 03:11:04,138] {taskinstance.py:1551} INFO - Marking task as UP_FOR_RETRY. dag_id=mssql_dag, task_id=clean1_contract, execution_date=20241010T031058, start_date=20241010T031103, end_date=20241010T031104
[2024-10-10 03:11:04,197] {local_task_job.py:149} INFO - Task exited with return code 1
