[2024-10-10 03:55:45,217] {taskinstance.py:896} INFO - Dependencies all met for <TaskInstance: mssql_dag.clean1_member 2024-10-10T03:50:36.124646+00:00 [queued]>
[2024-10-10 03:55:45,225] {taskinstance.py:896} INFO - Dependencies all met for <TaskInstance: mssql_dag.clean1_member 2024-10-10T03:50:36.124646+00:00 [queued]>
[2024-10-10 03:55:45,225] {taskinstance.py:1087} INFO - 
--------------------------------------------------------------------------------
[2024-10-10 03:55:45,226] {taskinstance.py:1088} INFO - Starting attempt 2 of 2
[2024-10-10 03:55:45,227] {taskinstance.py:1089} INFO - 
--------------------------------------------------------------------------------
[2024-10-10 03:55:45,235] {taskinstance.py:1107} INFO - Executing <Task(PythonOperator): clean1_member> on 2024-10-10T03:50:36.124646+00:00
[2024-10-10 03:55:45,240] {standard_task_runner.py:52} INFO - Started process 14625 to run task
[2024-10-10 03:55:45,243] {standard_task_runner.py:76} INFO - Running: ['***', 'tasks', 'run', 'mssql_dag', 'clean1_member', '2024-10-10T03:50:36.124646+00:00', '--job-id', '413', '--pool', 'default_pool', '--raw', '--subdir', 'DAGS_FOLDER/mssql_dag.py', '--cfg-path', '/tmp/tmp34jr6qwj', '--error-file', '/tmp/tmpjrqaghug']
[2024-10-10 03:55:45,251] {standard_task_runner.py:77} INFO - Job 413: Subtask clean1_member
[2024-10-10 03:55:45,299] {logging_mixin.py:104} INFO - Running <TaskInstance: mssql_dag.clean1_member 2024-10-10T03:50:36.124646+00:00 [running]> on host da843a407010
[2024-10-10 03:55:45,329] {taskinstance.py:1302} INFO - Exporting the following env vars:
AIRFLOW_CTX_DAG_OWNER=***
AIRFLOW_CTX_DAG_ID=mssql_dag
AIRFLOW_CTX_TASK_ID=clean1_member
AIRFLOW_CTX_EXECUTION_DATE=2024-10-10T03:50:36.124646+00:00
AIRFLOW_CTX_DAG_RUN_ID=manual__2024-10-10T03:50:36.124646+00:00
[2024-10-10 03:55:45,337] {taskinstance.py:1501} ERROR - Task failed with exception
Traceback (most recent call last):
  File "/home/airflow/.local/lib/python3.6/site-packages/airflow/models/taskinstance.py", line 1157, in _run_raw_task
    self._prepare_and_execute_task_with_callbacks(context, task)
  File "/home/airflow/.local/lib/python3.6/site-packages/airflow/models/taskinstance.py", line 1331, in _prepare_and_execute_task_with_callbacks
    result = self._execute_task(context, task_copy)
  File "/home/airflow/.local/lib/python3.6/site-packages/airflow/models/taskinstance.py", line 1361, in _execute_task
    result = task_copy.execute(context=context)
  File "/home/airflow/.local/lib/python3.6/site-packages/airflow/operators/python.py", line 150, in execute
    return_value = self.execute_callable()
  File "/home/airflow/.local/lib/python3.6/site-packages/airflow/operators/python.py", line 161, in execute_callable
    return self.python_callable(*self.op_args, **self.op_kwargs)
  File "/opt/airflow/dags/mssql_dag.py", line 286, in clean1_member
    df_member[columns_to_clean] = df_member[columns_to_clean].apply(lambda x: x.str.strip().replace('', None))
  File "/home/airflow/.local/lib/python3.6/site-packages/pandas/core/frame.py", line 2912, in __getitem__
    indexer = self.loc._get_listlike_indexer(key, axis=1, raise_missing=True)[1]
  File "/home/airflow/.local/lib/python3.6/site-packages/pandas/core/indexing.py", line 1254, in _get_listlike_indexer
    self._validate_read_indexer(keyarr, indexer, axis, raise_missing=raise_missing)
  File "/home/airflow/.local/lib/python3.6/site-packages/pandas/core/indexing.py", line 1298, in _validate_read_indexer
    raise KeyError(f"None of [{key}] are in the [{axis_name}]")
KeyError: "None of [Index(['MAST_PAID_AMT', 'MAST_PAID_SHR', 'MAST_SAL_TO_COOP',\n       'MAST_SAL_TO_BANK', 'MAST_REP_PAY_AMT', 'MAST_RETIRE_SALARY',\n       'MAST_FINE_AMT'],\n      dtype='object')] are in the [columns]"
[2024-10-10 03:55:45,426] {taskinstance.py:1551} INFO - Marking task as FAILED. dag_id=mssql_dag, task_id=clean1_member, execution_date=20241010T035036, start_date=20241010T035545, end_date=20241010T035545
[2024-10-10 03:55:45,502] {local_task_job.py:149} INFO - Task exited with return code 1
